<?xml version="1.0"?>
<robot name="robot" xmlns:xacro="http://wiki.ros.org/xacro">

  <xacro:macro name="wheel" params="r p w x y z name parent">
    <joint name="${name}_joint" type="continuous">
      <limit effort="100.00000" velocity="100.00000"/>
      <origin rpy="${r} ${p} ${w}" xyz="${x} ${y} ${z}"/>
      <parent link="${parent}"/>
      <child link="${name}"/>
      <axis xyz="0.00000 0.00000 1.00000"/>
    </joint>
    <link name="${name}">
      <collision name="${name}_collision">
        <origin rpy="0 0 0" xyz="0 0 0"/>
        <geometry>
          <cylinder radius="0.25" length="0.2"/>
        </geometry>
        <surface>
          <friction>
            <ode>
              <mu>1.000000</mu>
              <mu2>1.000000</mu2>
              <slip1>0.50000</slip1>
              <slip2>0.50000</slip2>
            </ode>
          </friction>
        </surface>
      </collision>
      <inertial>
        <origin rpy="0 0 0" xyz="0 0 0"/>
        <mass value="1.0"/>
        <inertia ixx="0.03125" ixy="0" ixz="0" iyy="0.01896" iyz="0" izz="0.01896"/>
      </inertial>
      <visual name="${name}_visual">
        <origin rpy="0 0 0" xyz="0 0 0"/>
        <material name="black"/>
        <geometry>
          <cylinder radius="0.25" length="0.2"/>
        </geometry>
      </visual>
    </link>

    <transmission name="${name}_transmission">
      <type>transmission_interface/SimpleTransmission</type>
      <joint name="${name}_joint">
        <hardwareInterface>hardware_interface/VelocityJointInterface</hardwareInterface>
      </joint>
      <actuator name="${name}_motor">
        <mechanicalReduction>1.0</mechanicalReduction>
      </actuator>
    </transmission>
    <gazebo reference="${name}">
      <mu1>5</mu1>
      <mu2>5</mu2>
      <!--kp>2.75e6</kp>
      <kd>8.25e1</kd>
      <fdir1>0 0 0</fdir1>
      <maxContacs>4</maxContacs--> 
    </gazebo>
  </xacro:macro>

  <material name="black">
    <color rgba="0.00000 0.00000 0.00000 1.00000"/>
  </material>

</robot>