<?xml version="1.0"?>
<robot name="robot" xmlns:xacro="http://wiki.ros.org/xacro">

  <xacro:macro name="arm" params="parent">
    <joint name="Brazo_L1_link_joint" type="fixed">
      <origin rpy="1.57080 0.00000 -1.57080" xyz="1.00000 0.00000 0.00000"/>
      <parent link="Union_base_L1_link"/>
      <child link="Brazo_L1_link"/>
    </joint>
    <joint name="Brazo_L2_link_joint" type="fixed">
      <origin rpy="1.57080 0.00000 -1.57080" xyz="0.85000 0.00000 0.00000"/>
      <parent link="Union_eje_L2_link"/>
      <child link="Brazo_L2_link"/>
    </joint>
    <joint name="Brazo_L3_link_joint" type="prismatic">
      <limit lower="0.00000" upper="1.70000" effort="50.0" velocity="1.5"/>
      <origin rpy="0.00000 0.00000 1.57080" xyz="0.00000 0.00000 -1.00000"/>
      <parent link="Union_L2_L3_link"/>
      <child link="Brazo_L3_link"/>
      <axis xyz="0.00000 0.00000 1.00000"/>
    </joint>
    <joint name="Brazo_base_link_joint" type="fixed">
      <origin rpy="0.00000 0.00000 0.00000" xyz="0.00000 -0.25000 1.00000"/>
      <parent link="${parent}"/>
      <child link="Brazo_base_link"/>
    </joint>
    <joint name="Union_L1_L2_link_joint" type="fixed">
      <origin rpy="0.00000 0.00000 0.00000" xyz="0.00000 0.00000 -0.25000"/>
      <parent link="Union_L1_eje_link"/>
      <child link="Union_L1_L2_link"/>
    </joint>
    <joint name="Union_L1_eje_link_joint" type="fixed">
      <origin rpy="-1.57080 0.00000 0.00000" xyz="0.00000 -0.00000 -0.90000"/>
      <parent link="Brazo_L1_link"/>
      <child link="Union_L1_eje_link"/>
    </joint>
    <joint name="Union_L2_L3_link_joint" type="fixed">
      <origin rpy="-1.57080 0.00000 0.00000" xyz="0.00000 -0.00000 -0.75000"/>
      <parent link="Brazo_L2_link"/>
      <child link="Union_L2_L3_link"/>
    </joint>
    <joint name="Union_base_L1_link_joint" type="revolute">
      <limit lower="-2.50000" upper="2.50000" effort="50.0" velocity="1.5"/>
      <origin rpy="0.00000 0.00000 1.57080" xyz="0.00000 0.00000 1.00000"/>
      <parent link="Brazo_base_link"/>
      <child link="Union_base_L1_link"/>
      <axis xyz="0.00000 0.00000 1.00000"/>
    </joint>
    <joint name="Union_eje_L2_link_joint" type="revolute">
      <limit lower="-2.50000" upper="2.50000" effort="50.0" velocity="1.5"/>
      <origin rpy="0.00000 0.00000 1.57080" xyz="0.00000 0.00000 -0.25000"/>
      <parent link="Union_L1_L2_link"/>
      <child link="Union_eje_L2_link"/>
      <axis xyz="0.00000 0.00000 1.00000"/>
    </joint>
    <link name="Brazo_L1_link">
      <collision name="Brazo_L1_collision">
        <origin rpy="-0.00000 0.00000 0.00000" xyz="0.00000 0.00000 0.00000"/>
        <geometry>
          <cylinder radius="0.15000" length="1.70000"/>
        </geometry>
      </collision>
      <inertial>
        <inertia ixx="0.49292" ixy="0.00000" ixz="0.00000" iyy="0.02250" iyz="-0.00000" izz="0.49292"/>
        <origin rpy="0.00000 0.00000 0.00000" xyz="0.00000 -0.00000 0.00000"/>
        <mass value="2.00000"/>
      </inertial>
      <visual name="Brazo_L1">
        <origin rpy="0.00000 0.00000 0.00000" xyz="0.00000 0.00000 0.00000"/>
        <material name="ligth_blue"/>
        <geometry>
          <cylinder radius="0.15000" length="1.70000"/>
        </geometry>
      </visual>
    </link>
    <link name="Brazo_L2_link">
      <collision name="Brazo_L2_collision">
        <origin rpy="0.00000 0.00000 0.00000" xyz="0.00000 0.00000 0.00000"/>
        <geometry>
          <cylinder radius="0.15000" length="1.50000"/>
        </geometry>
      </collision>
      <inertial>
        <inertia ixx="0.38625" ixy="0.00000" ixz="0.00000" iyy="0.02250" iyz="-0.00000" izz="0.38625"/>
        <origin rpy="0.00000 0.00000 0.00000" xyz="0.00000 0.00000 0.00000"/>
        <mass value="2.00000"/>
      </inertial>
      <visual name="Brazo_L2">
        <origin rpy="0.00000 0.00000 0.00000" xyz="0.00000 0.00000 0.00000"/>
        <material name="ligth_blue"/>
        <geometry>
          <cylinder radius="0.15000" length="1.50000"/>
        </geometry>
      </visual>
    </link>
    <link name="Brazo_L3_link">
      <collision name="Brazo_L3_collision">
        <origin rpy="0.00000 0.00000 0.00000" xyz="0.00000 0.00000 0.00000"/>
        <geometry>
          <cylinder radius="0.15000" length="2.00000"/>
        </geometry>
      </collision>
      <inertial>
        <inertia ixx="0.67792" ixy="0.00000" ixz="0.00000" iyy="0.67792" iyz="0.00000" izz="0.02250"/>
        <origin rpy="0.00000 0.00000 0.00000" xyz="0.00000 0.00000 0.00000"/>
        <mass value="2.00000"/>
      </inertial>
      <visual name="Brazo_L3">
        <origin rpy="0.00000 0.00000 0.00000" xyz="0.00000 0.00000 0.00000"/>
        <material name="ligth_blue"/>
        <geometry>
          <cylinder radius="0.15000" length="2.00000"/>
        </geometry>
      </visual>
    </link>
    <link name="Brazo_base_link">
      <collision name="Brazo_base_collision">
        <origin rpy="0.00000 0.00000 0.00000" xyz="0.00000 0.00000 0.00000"/>
        <geometry>
          <cylinder radius="0.15000" length="2.30000"/>
        </geometry>
      </collision>
      <inertial>
        <inertia ixx="4.46458" ixy="0.00000" ixz="0.00000" iyy="4.46458" iyz="0.00000" izz="0.11250"/>
        <origin rpy="0.00000 0.00000 0.00000" xyz="0.00000 0.00000 0.00000"/>
        <mass value="10.00000"/>
      </inertial>
      <visual name="Brazo_base">
        <origin rpy="0.00000 0.00000 0.00000" xyz="0.00000 0.00000 0.00000"/>
        <material name="ligth_blue"/>
        <geometry>
          <cylinder radius="0.15000" length="2.30000"/>
        </geometry>
      </visual>
    </link>
    <link name="Union_L1_L2_link">
      <collision name="Union_L1_L2_collision">
        <origin rpy="0.00000 0.00000 0.00000" xyz="0.00000 0.00000 0.00000"/>
        <geometry>
          <cylinder radius="0.15000" length="0.75000"/>
        </geometry>
      </collision>
      <inertial>
        <inertia ixx="0.05250" ixy="0.00000" ixz="0.00000" iyy="0.05250" iyz="0.00000" izz="0.01125"/>
        <origin rpy="0.00000 0.00000 0.00000" xyz="0.00000 0.00000 0.00000"/>
        <mass value="1.00000"/>
      </inertial>
      <visual name="Union_L1_L2">
        <origin rpy="0.00000 0.00000 0.00000" xyz="0.00000 0.00000 0.00000"/>
        <material name="ligth_blue"/>
        <geometry>
          <cylinder radius="0.15000" length="0.75000"/>
        </geometry>
      </visual>
    </link>
    <link name="Union_L1_eje_link">
      <collision name="Union_L1_eje_collision">
        <origin rpy="0.00000 0.00000 0.00000" xyz="0.00000 0.00000 0.00000"/>
        <geometry>
          <sphere radius="0.25000"/>
        </geometry>
      </collision>
      <inertial>
        <inertia ixx="0.02500" ixy="0.00000" ixz="0.00000" iyy="0.02500" iyz="0.00000" izz="0.02500"/>
        <origin rpy="0.00000 0.00000 0.00000" xyz="0.00000 0.00000 0.00000"/>
        <mass value="1.00000"/>
      </inertial>
      <visual name="Union_L1_eje">
        <origin rpy="0.00000 0.00000 0.00000" xyz="0.00000 0.00000 0.00000"/>
        <material name="ligth_grey"/>
        <geometry>
          <sphere radius="0.25000"/>
        </geometry>
      </visual>
    </link>
    <link name="Union_L2_L3_link">
      <collision name="Union_L2_L3_collision">
        <origin rpy="0.00000 0.00000 0.00000" xyz="0.00000 0.00000 0.00000"/>
        <geometry>
          <sphere radius="0.25000"/>
        </geometry>
      </collision>
      <inertial>
        <inertia ixx="0.02500" ixy="0.00000" ixz="0.00000" iyy="0.02500" iyz="0.00000" izz="0.02500"/>
        <origin rpy="0.00000 0.00000 0.00000" xyz="0.00000 0.00000 0.00000"/>
        <mass value="1.00000"/>
      </inertial>
      <visual name="Union_L2_L3">
        <origin rpy="0.00000 0.00000 0.00000" xyz="0.00000 0.00000 0.00000"/>
        <material name="ligth_grey"/>
        <geometry>
          <sphere radius="0.25000"/>
        </geometry>
      </visual>
    </link>
    <link name="Union_base_L1_link">
      <collision name="Union_base_L1_collision">
        <origin rpy="0.00000 0.00000 0.00000" xyz="0.00000 0.00000 0.00000"/>
        <geometry>
          <sphere radius="0.25000"/>
        </geometry>
      </collision>
      <inertial>
        <inertia ixx="0.02500" ixy="0.00000" ixz="0.00000" iyy="0.02500" iyz="0.00000" izz="0.02500"/>
        <origin rpy="0.00000 0.00000 0.00000" xyz="0.00000 0.00000 0.00000"/>
        <mass value="1.00000"/>
      </inertial>
      <visual name="Union_base_L1">
        <origin rpy="0.00000 0.00000 0.00000" xyz="0.00000 0.00000 0.00000"/>
        <material name="ligth_grey"/>
        <geometry>
          <sphere radius="0.25000"/>
        </geometry>
      </visual>
    </link>
    <link name="Union_eje_L2_link">
      <collision name="Union_eje_L2_collision">
        <origin rpy="0.00000 0.00000 0.00000" xyz="0.00000 0.00000 0.00000"/>
        <geometry>
          <sphere radius="0.25000"/>
        </geometry>
      </collision>
      <inertial>
        <inertia ixx="0.02500" ixy="0.00000" ixz="0.00000" iyy="0.02500" iyz="0.00000" izz="0.02500"/>
        <origin rpy="0.00000 0.00000 0.00000" xyz="0.00000 0.00000 0.00000"/>
        <mass value="1.00000"/>
      </inertial>
      <visual name="Union_eje_L2">
        <origin rpy="0.00000 0.00000 0.00000" xyz="0.00000 0.00000 0.00000"/>
        <material name="ligth_grey"/>
        <geometry>
          <sphere radius="0.25000"/>
        </geometry>
      </visual>
    </link>
  </xacro:macro>

  <material name="ligth_blue">
    <color rgba="0.55686 0.55686 0.55686 1.00000"/>
  </material>
  <material name="ligth_grey">
    <color rgba="0.04706 0.39608 0.51765 1.00000"/>
  </material>
</robot>